# -*- coding: utf-8 -*-
import re
import traceback

from flask import current_app as _app, request, g, jsonify
from pydantic import ValidationError

from apps.system.models.error_record import SystemErrorRecord
from utils.message.send_report import send_system_error


def register_errorhandler_hook(app):
    """ 注册异常捕获钩子函数 """

    @app.errorhandler(400)
    def forbidden_400(e):
        """ 捕获400异常 """
        return _app.restful.fail(e.description)

    @app.errorhandler(401)
    def forbidden_401(e):
        """ 捕获401的未登录异常 """
        return _app.restful.not_login(
            _app.config["SSO"].front_redirect_addr if _app.config["AUTH_TYPE"] == "SSO" else None)

    @app.errorhandler(403)
    def forbidden_403(e):
        """ 捕获403的权限不足异常 """
        return _app.restful.forbidden()

    @app.errorhandler(404)
    def page_not_found(e):
        """ 捕获404的所有异常 """
        if request.method != "HEAD":
            _app.logger.exception(f'【{g.get("request_id")}】404错误: {request.path}')
        return _app.restful.url_not_find(_app.config["URL_NOT_FIND_MSG"] or f'接口 {request.path} 不存在')

    @app.errorhandler(405)
    def method_error(e):
        """ 捕获405异常 """
        if request.method != "HEAD":
            _app.logger.exception(f'【{g.get("request_id")}】405错误: {request.method} {request.path}')
        return _app.restful.method_error()

    @app.errorhandler(500)
    def system_error(e):
        """ 捕获500异常 """
        if request.path.startswith('/api/tools/mock/'):  # mock脚本执行报错的，抛出异常
            response = jsonify({'code': 500, 'msg': f'执行mock脚本错误：{request.path}', 'data': None})
            response.status_code = 500
            return response

    @app.errorhandler(ValidationError)
    def pydantic_cls_validation_error(exc):
        """ pydantic数据校验不通过
        {
            'input': {
                'business_id': 16, 'id': None, 'manager': 1, 'name': '123', 'script_list': []
            },
            'loc': ('swagger',),
            'msg': 'Field required',
            'type': 'missing',
            'url': 'https://errors.pydantic.dev/2.4/v/missing'
        }
        """
        error = exc.errors()[0]
        request_data, filed_name, error_type, msg = error["input"], error["loc"][-1], error["type"], error["msg"]
        filed_title = g.current_from.get_filed_title(filed_name)
        if "type" in error_type or error_type == "int_parsing":  # 数据类型错误
            return _app.restful.fail(f'{filed_title} 数据类型错误')

        elif "required" in msg:  # 必传字段
            return _app.restful.fail(f'{filed_title} 必传')

        elif "value_error" in error_type:  # 数据验证不通过
            # 'Value error, 服务名【xxxx】已存在'
            return _app.restful.fail(msg.split(', ', 1)[1])

        elif "enum" in error_type:  # 枚举错误
            return _app.restful.fail(f'{filed_title} 枚举错误：{msg}')

        elif "max_length" in error_type:  # 数据长度超长
            return _app.restful.fail(f'{filed_title} 长度超长，最多{error["ctx"]["min_length"]}位')

        elif msg == "List should have at least 1 item after validation, not 0":  # 空列表
            return _app.restful.fail(f'最少选择{error["ctx"]["min_length"]}个{filed_title}')

        elif "string_too_short" in error_type:  # 数据长度不够
            return _app.restful.fail(f'{filed_title} 长度不够，最少{error["ctx"]["min_length"]}位')

        return _app.restful.fail(f'系统错误：{error}')

    @app.errorhandler(ValueError)
    def pydantic_self_validation_error(exc):
        """ pydantic实例依赖数据校验不通过
            ValueError('头部信息设置，第【1】行，要设置参数，则key和value都需设置')
        """
        return _app.restful.fail(exc.args[0])

    @app.errorhandler(Exception)
    def error_handler_500(e):
        """ 捕获所有服务器内部的异常，把错误发送到 即时达推送 的 系统错误 通道 """
        try:
            original = getattr(e, "orig", None)
            if original:
                error_code, error_msg = getattr(original, "args", None)
                if "Duplicate" in error_msg:  # 数据重复
                    filed_value = re.findall("'(.+?)'", error_msg)[0]
                    return _app.restful.fail(f'{filed_value} 已存在')
                elif "Data too long" in error_msg:  # 数据超长
                    return _app.restful.fail(error_msg)
                return _app.restful.fail(error_msg)

        except:
            pass
        error = traceback.format_exc()
        try:
            _app.logger.exception(
                f'【{g.get("request_id")}】系统报错了:  \n\n url: {request.path} \n\n 错误详情: \n\n {error}')

            # 写数据库
            error_record = SystemErrorRecord.model_create_and_get({
                "url": request.path,
                "method": request.method,
                "headers": dict(request.headers),
                "params": request.args or {},
                "data_form": request.form or {},
                "data_json": request.json if request.content_type and "json" in request.content_type else {},
                "detail": error
            })

            # 发送即时通讯通知
            send_system_error(title=f'{_app.config["SECRET_KEY"]}报错通知，数据id：{error_record.id}', content=error)
        except Exception as error:
            _app.logger.exception(
                f'【{g.get("request_id")}】系统报错了:  \n\n url: {request.path} \n\n 错误详情: \n\n {error}')

        return _app.restful.error(f'服务器异常: {e}')
